Workbook

Sheet Start
C2: Berlin & Potsdam Family Travel Budget Planner & Expense Tracker
C3: Effortlessly manage your family travel budget and expenses with this professional Excel template, designed for stress-free planning and tracking.
C5: How it works
B6: 1. | C6: Enter your trip details and budget goals.
B7: 2. | C7: Track daily expenses with categories like Accommodation, Food, Transport, and Activities.
B8: 3. | C8: Monitor your remaining budget and adjust plans accordingly.
B9: 4. | C9: Use the itinerary sheet to schedule daily activities and sightseeing.
B10: 5. | C10: Review the KPI dashboard for a quick overview of your spending and savings.
C12: Only fill in white cells – green columns calculate automatically.
C14: Go to sheet
C15: → Dashboard
C16: → Budget
C17: → ExchangeRates
C18: → Itinerary
C20: Made by Haiktec · haiktec.tech

Sheet Dashboard
B2: Dashboard – Berlin & Potsdam Family Travel Budget Planner & Expense Trac
B4: Key figures
B5: Total Expenses | C5: =SUM('Budget'!E2:E300)
B6: Daily Average Spend | C6: =AVERAGE('Budget'!C2:C300)
B7: Number of Transactions | C7: =COUNTA('Budget'!A2:A300)
B8: Top Spending Category | C8: =INDEX('Budget'!B2:B300,MATCH(MAX('Budget'!C2:C300),'Budget'!C2:C300,0))

Sheet Budget
A1: Date | B1: Category | C1: Amount | D1: Currency | E1: Conversion to EUR
A2: 46037 | B2: Accommodation | C2: 150 | D2: EUR | E2: =IF(D2="EUR",C2,C2*VLOOKUP(D2,'ExchangeRates'!A2:B10,2,FALSE))
A3: 46038 | B3: Food | C3: 50 | D3: EUR | E3: =IF(D3="EUR",C3,C3*VLOOKUP(D3,'ExchangeRates'!A2:B10,2,FALSE))
A4: 46039 | B4: Transport | C4: 20 | D4: EUR | E4: =IF(D4="EUR",C4,C4*VLOOKUP(D4,'ExchangeRates'!A2:B10,2,FALSE))
A5: 46040 | B5: Activities | C5: 30 | D5: EUR | E5: =IF(D5="EUR",C5,C5*VLOOKUP(D5,'ExchangeRates'!A2:B10,2,FALSE))
E6: =IF(A6="","",IF(D6="EUR",C6,C6*VLOOKUP(D6,'ExchangeRates'!A2:B10,2,FALSE)))
E7: =IF(A7="","",IF(D7="EUR",C7,C7*VLOOKUP(D7,'ExchangeRates'!A2:B10,2,FALSE)))
E8: =IF(A8="","",IF(D8="EUR",C8,C8*VLOOKUP(D8,'ExchangeRates'!A2:B10,2,FALSE)))
E9: =IF(A9="","",IF(D9="EUR",C9,C9*VLOOKUP(D9,'ExchangeRates'!A2:B10,2,FALSE)))
E10: =IF(A10="","",IF(D10="EUR",C10,C10*VLOOKUP(D10,'ExchangeRates'!A2:B10,2,FALSE)))
E11: =IF(A11="","",IF(D11="EUR",C11,C11*VLOOKUP(D11,'ExchangeRates'!A2:B10,2,FALSE)))
E12: =IF(A12="","",IF(D12="EUR",C12,C12*VLOOKUP(D12,'ExchangeRates'!A2:B10,2,FALSE)))
E13: =IF(A13="","",IF(D13="EUR",C13,C13*VLOOKUP(D13,'ExchangeRates'!A2:B10,2,FALSE)))
E14: =IF(A14="","",IF(D14="EUR",C14,C14*VLOOKUP(D14,'ExchangeRates'!A2:B10,2,FALSE)))
E15: =IF(A15="","",IF(D15="EUR",C15,C15*VLOOKUP(D15,'ExchangeRates'!A2:B10,2,FALSE)))
E16: =IF(A16="","",IF(D16="EUR",C16,C16*VLOOKUP(D16,'ExchangeRates'!A2:B10,2,FALSE)))
E17: =IF(A17="","",IF(D17="EUR",C17,C17*VLOOKUP(D17,'ExchangeRates'!A2:B10,2,FALSE)))
E18: =IF(A18="","",IF(D18="EUR",C18,C18*VLOOKUP(D18,'ExchangeRates'!A2:B10,2,FALSE)))
E19: =IF(A19="","",IF(D19="EUR",C19,C19*VLOOKUP(D19,'ExchangeRates'!A2:B10,2,FALSE)))
E20: =IF(A20="","",IF(D20="EUR",C20,C20*VLOOKUP(D20,'ExchangeRates'!A2:B10,2,FALSE)))
E21: =IF(A21="","",IF(D21="EUR",C21,C21*VLOOKUP(D21,'ExchangeRates'!A2:B10,2,FALSE)))
E22: =IF(A22="","",IF(D22="EUR",C22,C22*VLOOKUP(D22,'ExchangeRates'!A2:B10,2,FALSE)))
E23: =IF(A23="","",IF(D23="EUR",C23,C23*VLOOKUP(D23,'ExchangeRates'!A2:B10,2,FALSE)))
E24: =IF(A24="","",IF(D24="EUR",C24,C24*VLOOKUP(D24,'ExchangeRates'!A2:B10,2,FALSE)))
E25: =IF(A25="","",IF(D25="EUR",C25,C25*VLOOKUP(D25,'ExchangeRates'!A2:B10,2,FALSE)))
E26: =IF(A26="","",IF(D26="EUR",C26,C26*VLOOKUP(D26,'ExchangeRates'!A2:B10,2,FALSE)))
E27: =IF(A27="","",IF(D27="EUR",C27,C27*VLOOKUP(D27,'ExchangeRates'!A2:B10,2,FALSE)))
E28: =IF(A28="","",IF(D28="EUR",C28,C28*VLOOKUP(D28,'ExchangeRates'!A2:B10,2,FALSE)))
E29: =IF(A29="","",IF(D29="EUR",C29,C29*VLOOKUP(D29,'ExchangeRates'!A2:B10,2,FALSE)))
E30: =IF(A30="","",IF(D30="EUR",C30,C30*VLOOKUP(D30,'ExchangeRates'!A2:B10,2,FALSE)))
E31: =IF(A31="","",IF(D31="EUR",C31,C31*VLOOKUP(D31,'ExchangeRates'!A2:B10,2,FALSE)))
E32: =IF(A32="","",IF(D32="EUR",C32,C32*VLOOKUP(D32,'ExchangeRates'!A2:B10,2,FALSE)))
E33: =IF(A33="","",IF(D33="EUR",C33,C33*VLOOKUP(D33,'ExchangeRates'!A2:B10,2,FALSE)))
E34: =IF(A34="","",IF(D34="EUR",C34,C34*VLOOKUP(D34,'ExchangeRates'!A2:B10,2,FALSE)))
E35: =IF(A35="","",IF(D35="EUR",C35,C35*VLOOKUP(D35,'ExchangeRates'!A2:B10,2,FALSE)))
E36: =IF(A36="","",IF(D36="EUR",C36,C36*VLOOKUP(D36,'ExchangeRates'!A2:B10,2,FALSE)))
E37: =IF(A37="","",IF(D37="EUR",C37,C37*VLOOKUP(D37,'ExchangeRates'!A2:B10,2,FALSE)))
E38: =IF(A38="","",IF(D38="EUR",C38,C38*VLOOKUP(D38,'ExchangeRates'!A2:B10,2,FALSE)))
E39: =IF(A39="","",IF(D39="EUR",C39,C39*VLOOKUP(D39,'ExchangeRates'!A2:B10,2,FALSE)))
E40: =IF(A40="","",IF(D40="EUR",C40,C40*VLOOKUP(D40,'ExchangeRates'!A2:B10,2,FALSE)))
...

Sheet ExchangeRates
A1: Currency | B1: Rate
A2: USD | B2: 0.92
A3: GBP | B3: 1.15
A4: CHF | B4: 0.95

Sheet Itinerary
A1: Date | B1: Time | C1: Activity | D1: Location | E1: Estimated Cost
A2: 46037 | B2: 10:00 | C2: Brandenburg Gate | D2: Berlin | E2: 0
A3: 46037 | B3: 14:00 | C3: Lunch | D3: Berlin | E3: 20
A4: 46038 | B4: 09:00 | C4: Potsdam Palace | D4: Potsdam | E4: 10
A5: 46038 | B5: 12:00 | C5: Lunch | D5: Potsdam | E5: 15
