Workbook

Sheet Start
C2: Mitgliederbeitrags-Tracker & Finanzplaner für Vereine
C3: Professionelle Excel-Lösung zur einfachen Verwaltung von Mitgliedsbeiträgen und Vereinsfinanzen. Spart Zeit und gibt volle Kontrolle über Einnahmen und Ausgaben.
C5: So funktioniert's
B6: 1. | C6: Mitgliederdaten im Blatt 'Mitglieder' erfassen
B7: 2. | C7: Beiträge und Zahlungseingänge im Blatt 'Beiträge' eintragen
B8: 3. | C8: Ausgaben im Blatt 'Buchhaltung' erfassen
B9: 4. | C9: Dashboard für schnellen Überblick nutzen
B10: 5. | C10: Monatliche Beiträge über die Beitragsliste tracken
B11: 6. | C11: Zahlungserinnerungen gemäß Fälligkeiten versenden
C13: Nur weiße Zellen ausfüllen – grüne Spalten rechnen automatisch.
C15: Zum Blatt
C16: → Übersicht
C17: → Mitglieder
C18: → Beiträge
C19: → Buchhaltung
C21: Erstellt von Haiktec · haiktec.tech

Sheet Übersicht
B2: Übersicht – Mitgliederbeitrags-Tracker & Finanzplaner für Vereine
B4: Kennzahlen
B5: Mitglieder gesamt | C5: =COUNTA(Mitglieder!A2:A300)
B6: Aktive Mitglieder | C6: =COUNTIF(Mitglieder!H2:H300,"aktiv")
B7: Beitragseinnahmen | C7: =SUM(Beiträge!D2:D300)
B8: Ausgaben | C8: =SUM(Buchhaltung!D2:D300)
B9: Kassenbestand | C9: =SUM(Beiträge!D2:D300)-SUM(Buchhaltung!D2:D300)
B10: Ausstehende Beiträge | C10: =SUMIF(Beiträge!H2:H300,"ausstehend",Beiträge!D2:D300)

Sheet Mitglieder
A1: Mitgliedsnummer | B1: Vorname | C1: Nachname | D1: Eintrittsdatum | E1: Beitragsart | F1: Beitragshoehe | G1: Zahlungsweise | H1: Status
A2: 1001 | B2: Max | C2: Mustermann | D2: 45731 | E2: Vollzahler | F2: 60 | G2: SEPA | H2: aktiv
A3: 1002 | B3: Anna | C3: Schmidt | D3: 46032 | E3: Ermässigt | F3: 30 | G3: Bar | H3: aktiv
A4: 1003 | B4: Thomas | C4: Bauer | D4: 45618 | E4: Vollzahler | F4: 60 | G4: Überweisung | H4: passiv

Sheet Beiträge
A1: Datum | B1: Mitgliedsnummer | C1: Name | D1: Betrag | E1: Zahlungsart | F1: Jahr | G1: Quittung | H1: Status
A2: 46027 | B2: 1001 | C2: =VLOOKUP(B2,Mitglieder!A2:H200,2,FALSE)&" "&VLOOKUP(B2,Mitglieder!A2:H200,3,FALSE) | D2: 60 | E2: SEPA | F2: 2026 | G2: JA | H2: bezahlt
A3: 46034 | B3: 1002 | C3: =VLOOKUP(B3,Mitglieder!A2:H200,2,FALSE)&" "&VLOOKUP(B3,Mitglieder!A2:H200,3,FALSE) | D3: 30 | E3: Bar | F3: 2026 | G3: NEIN | H3: bezahlt
A4: 46040 | B4: 1003 | C4: =VLOOKUP(B4,Mitglieder!A2:H200,2,FALSE)&" "&VLOOKUP(B4,Mitglieder!A2:H200,3,FALSE) | D4: 60 | E4: Überweisung | F4: 2026 | G4: JA | H4: ausstehend
C5: =IF(A5="","",VLOOKUP(B5,Mitglieder!A2:H200,2,FALSE)&" "&VLOOKUP(B5,Mitglieder!A2:H200,3,FALSE))
C6: =IF(A6="","",VLOOKUP(B6,Mitglieder!A2:H200,2,FALSE)&" "&VLOOKUP(B6,Mitglieder!A2:H200,3,FALSE))
C7: =IF(A7="","",VLOOKUP(B7,Mitglieder!A2:H200,2,FALSE)&" "&VLOOKUP(B7,Mitglieder!A2:H200,3,FALSE))
C8: =IF(A8="","",VLOOKUP(B8,Mitglieder!A2:H200,2,FALSE)&" "&VLOOKUP(B8,Mitglieder!A2:H200,3,FALSE))
C9: =IF(A9="","",VLOOKUP(B9,Mitglieder!A2:H200,2,FALSE)&" "&VLOOKUP(B9,Mitglieder!A2:H200,3,FALSE))
C10: =IF(A10="","",VLOOKUP(B10,Mitglieder!A2:H200,2,FALSE)&" "&VLOOKUP(B10,Mitglieder!A2:H200,3,FALSE))
C11: =IF(A11="","",VLOOKUP(B11,Mitglieder!A2:H200,2,FALSE)&" "&VLOOKUP(B11,Mitglieder!A2:H200,3,FALSE))
C12: =IF(A12="","",VLOOKUP(B12,Mitglieder!A2:H200,2,FALSE)&" "&VLOOKUP(B12,Mitglieder!A2:H200,3,FALSE))
C13: =IF(A13="","",VLOOKUP(B13,Mitglieder!A2:H200,2,FALSE)&" "&VLOOKUP(B13,Mitglieder!A2:H200,3,FALSE))
C14: =IF(A14="","",VLOOKUP(B14,Mitglieder!A2:H200,2,FALSE)&" "&VLOOKUP(B14,Mitglieder!A2:H200,3,FALSE))
C15: =IF(A15="","",VLOOKUP(B15,Mitglieder!A2:H200,2,FALSE)&" "&VLOOKUP(B15,Mitglieder!A2:H200,3,FALSE))
C16: =IF(A16="","",VLOOKUP(B16,Mitglieder!A2:H200,2,FALSE)&" "&VLOOKUP(B16,Mitglieder!A2:H200,3,FALSE))
C17: =IF(A17="","",VLOOKUP(B17,Mitglieder!A2:H200,2,FALSE)&" "&VLOOKUP(B17,Mitglieder!A2:H200,3,FALSE))
C18: =IF(A18="","",VLOOKUP(B18,Mitglieder!A2:H200,2,FALSE)&" "&VLOOKUP(B18,Mitglieder!A2:H200,3,FALSE))
C19: =IF(A19="","",VLOOKUP(B19,Mitglieder!A2:H200,2,FALSE)&" "&VLOOKUP(B19,Mitglieder!A2:H200,3,FALSE))
C20: =IF(A20="","",VLOOKUP(B20,Mitglieder!A2:H200,2,FALSE)&" "&VLOOKUP(B20,Mitglieder!A2:H200,3,FALSE))
C21: =IF(A21="","",VLOOKUP(B21,Mitglieder!A2:H200,2,FALSE)&" "&VLOOKUP(B21,Mitglieder!A2:H200,3,FALSE))
C22: =IF(A22="","",VLOOKUP(B22,Mitglieder!A2:H200,2,FALSE)&" "&VLOOKUP(B22,Mitglieder!A2:H200,3,FALSE))
C23: =IF(A23="","",VLOOKUP(B23,Mitglieder!A2:H200,2,FALSE)&" "&VLOOKUP(B23,Mitglieder!A2:H200,3,FALSE))
C24: =IF(A24="","",VLOOKUP(B24,Mitglieder!A2:H200,2,FALSE)&" "&VLOOKUP(B24,Mitglieder!A2:H200,3,FALSE))
C25: =IF(A25="","",VLOOKUP(B25,Mitglieder!A2:H200,2,FALSE)&" "&VLOOKUP(B25,Mitglieder!A2:H200,3,FALSE))
C26: =IF(A26="","",VLOOKUP(B26,Mitglieder!A2:H200,2,FALSE)&" "&VLOOKUP(B26,Mitglieder!A2:H200,3,FALSE))
C27: =IF(A27="","",VLOOKUP(B27,Mitglieder!A2:H200,2,FALSE)&" "&VLOOKUP(B27,Mitglieder!A2:H200,3,FALSE))
C28: =IF(A28="","",VLOOKUP(B28,Mitglieder!A2:H200,2,FALSE)&" "&VLOOKUP(B28,Mitglieder!A2:H200,3,FALSE))
C29: =IF(A29="","",VLOOKUP(B29,Mitglieder!A2:H200,2,FALSE)&" "&VLOOKUP(B29,Mitglieder!A2:H200,3,FALSE))
C30: =IF(A30="","",VLOOKUP(B30,Mitglieder!A2:H200,2,FALSE)&" "&VLOOKUP(B30,Mitglieder!A2:H200,3,FALSE))
C31: =IF(A31="","",VLOOKUP(B31,Mitglieder!A2:H200,2,FALSE)&" "&VLOOKUP(B31,Mitglieder!A2:H200,3,FALSE))
C32: =IF(A32="","",VLOOKUP(B32,Mitglieder!A2:H200,2,FALSE)&" "&VLOOKUP(B32,Mitglieder!A2:H200,3,FALSE))
C33: =IF(A33="","",VLOOKUP(B33,Mitglieder!A2:H200,2,FALSE)&" "&VLOOKUP(B33,Mitglieder!A2:H200,3,FALSE))
C34: =IF(A34="","",VLOOKUP(B34,Mitglieder!A2:H200,2,FALSE)&" "&VLOOKUP(B34,Mitglieder!A2:H200,3,FALSE))
C35: =IF(A35="","",VLOOKUP(B35,Mitglieder!A2:H200,2,FALSE)&" "&VLOOKUP(B35,Mitglieder!A2:H200,3,FALSE))
C36: =IF(A36="","",VLOOKUP(B36,Mitglieder!A2:H200,2,FALSE)&" "&VLOOKUP(B36,Mitglieder!A2:H200,3,FALSE))
C37: =IF(A37="","",VLOOKUP(B37,Mitglieder!A2:H200,2,FALSE)&" "&VLOOKUP(B37,Mitglieder!A2:H200,3,FALSE))
C38: =IF(A38="","",VLOOKUP(B38,Mitglieder!A2:H200,2,FALSE)&" "&VLOOKUP(B38,Mitglieder!A2:H200,3,FALSE))
C39: =IF(A39="","",VLOOKUP(B39,Mitglieder!A2:H200,2,FALSE)&" "&VLOOKUP(B39,Mitglieder!A2:H200,3,FALSE))
C40: =IF(A40="","",VLOOKUP(B40,Mitglieder!A2:H200,2,FALSE)&" "&VLOOKUP(B40,Mitglieder!A2:H200,3,FALSE))
...

Sheet Buchhaltung
A1: Datum | B1: Kategorie | C1: Beschreibung | D1: Betrag | E1: Zahlungsart | F1: Beleg
A2: 46032 | B2: Versammlung | C2: Raummiete Vereinsheim | D2: 120 | E2: Überweisung | F2: Rechnung 123
A3: 46037 | B3: Material | C3: Büromaterial | D3: 45.8 | E3: Bar | F3: Kassenzettel
A4: 46042 | B4: Veranstaltung | C4: Jahreshauptversammlung Catering | D4: 215.5 | E4: Überweisung | F4: Rechnung 456
