Workbook

Sheet Start
C2: Prüfungsvorbereitungs-Budget-Tracker & Lernplaner für Studierende
C3: Professionelle Excel-Vorlage zur Planung von Lernzeit und Budget für Prüfungen - behalte alle Kosten und Fortschritte im Überblick
C5: So funktioniert's
B6: 1. | C6: Trage alle Prüfungen mit Terminen ein
B7: 2. | C7: Plane wöchentliche Lernzeiten für jedes Fach
B8: 3. | C8: Erfasse Kosten für Lernmaterialien und Kurse
B9: 4. | C9: Tracke deine Lernfortschritte
B10: 5. | C10: Nutze die automatischen Auswertungen
B11: 6. | C11: Passe bei Bedarf deine Lernstrategie an
C13: Nur weiße Zellen ausfüllen – grüne Spalten rechnen automatisch.
C15: Zum Blatt
C16: → Übersicht
C17: → Pruefungen
C18: → Lernplan
C19: → Kosten
C21: Erstellt von Haiktec · haiktec.tech

Sheet Übersicht
B2: Übersicht – Prüfungsvorbereitungs-Budget-Tracker & Lernplaner für Studie
B4: Kennzahlen
B5: Gesamtkosten | C5: =SUM('Kosten'!D2:D100)
B6: Geplante Lernstunden | C6: =SUM('Lernplan'!C2:C100)
B7: Durchschnittliche Lernzeit pro Tag | C7: =AVERAGE('Lernplan'!C2:C100)
B8: Anzahl Prüfungen | C8: =COUNTA('Pruefungen'!A2:A100)
B9: Prozentuale Vorbereitung | C9: =AVERAGE('Lernplan'!E2:E100)

Sheet Pruefungen
A1: Pruefung | B1: Datum | C1: Prioritaet | D1: Status | E1: Notiz
A2: Mathematik I | B2: 46096 | C2: Hoch | D2: Offen | E2: Kapitel 1-3 wiederholen
A3: Betriebswirtschaft | B3: 46114 | C3: Mittel | D3: In Arbeit | E3: Fallstudien üben
A4: Englisch | B4: 46109 | C4: Niedrig | D4: Noch nicht begonnen | E4: Vokabeln lernen

Sheet Lernplan
A1: Datum | B1: Fach | C1: Stunden | D1: Thema | E1: Fortschritt
A2: 46038 | B2: Mathematik I | C2: 2.5 | D2: Differentialrechnung | E2: =(SUMIF('Lernfortschritt'!B2:B100,B2,'Lernfortschritt'!D2:D100))/VLOOKUP(B2,'Pruefungen'!A2:E100,2,FALSE)
A3: 46039 | B3: Betriebswirtschaft | C3: 3 | D3: Kostenrechnung | E3: =(SUMIF('Lernfortschritt'!B2:B100,B3,'Lernfortschritt'!D2:D100))/VLOOKUP(B3,'Pruefungen'!A2:E100,2,FALSE)
A4: 46040 | B4: Englisch | C4: 1.5 | D4: Business Vokabular | E4: =(SUMIF('Lernfortschritt'!B2:B100,B4,'Lernfortschritt'!D2:D100))/VLOOKUP(B4,'Pruefungen'!A2:E100,2,FALSE)
E5: =IF(A5="","",(SUMIF('Lernfortschritt'!B2:B100,B5,'Lernfortschritt'!D2:D100))/VLOOKUP(B5,'Pruefungen'!A2:E100,2,FALSE))
E6: =IF(A6="","",(SUMIF('Lernfortschritt'!B2:B100,B6,'Lernfortschritt'!D2:D100))/VLOOKUP(B6,'Pruefungen'!A2:E100,2,FALSE))
E7: =IF(A7="","",(SUMIF('Lernfortschritt'!B2:B100,B7,'Lernfortschritt'!D2:D100))/VLOOKUP(B7,'Pruefungen'!A2:E100,2,FALSE))
E8: =IF(A8="","",(SUMIF('Lernfortschritt'!B2:B100,B8,'Lernfortschritt'!D2:D100))/VLOOKUP(B8,'Pruefungen'!A2:E100,2,FALSE))
E9: =IF(A9="","",(SUMIF('Lernfortschritt'!B2:B100,B9,'Lernfortschritt'!D2:D100))/VLOOKUP(B9,'Pruefungen'!A2:E100,2,FALSE))
E10: =IF(A10="","",(SUMIF('Lernfortschritt'!B2:B100,B10,'Lernfortschritt'!D2:D100))/VLOOKUP(B10,'Pruefungen'!A2:E100,2,FALSE))
E11: =IF(A11="","",(SUMIF('Lernfortschritt'!B2:B100,B11,'Lernfortschritt'!D2:D100))/VLOOKUP(B11,'Pruefungen'!A2:E100,2,FALSE))
E12: =IF(A12="","",(SUMIF('Lernfortschritt'!B2:B100,B12,'Lernfortschritt'!D2:D100))/VLOOKUP(B12,'Pruefungen'!A2:E100,2,FALSE))
E13: =IF(A13="","",(SUMIF('Lernfortschritt'!B2:B100,B13,'Lernfortschritt'!D2:D100))/VLOOKUP(B13,'Pruefungen'!A2:E100,2,FALSE))
E14: =IF(A14="","",(SUMIF('Lernfortschritt'!B2:B100,B14,'Lernfortschritt'!D2:D100))/VLOOKUP(B14,'Pruefungen'!A2:E100,2,FALSE))
E15: =IF(A15="","",(SUMIF('Lernfortschritt'!B2:B100,B15,'Lernfortschritt'!D2:D100))/VLOOKUP(B15,'Pruefungen'!A2:E100,2,FALSE))
E16: =IF(A16="","",(SUMIF('Lernfortschritt'!B2:B100,B16,'Lernfortschritt'!D2:D100))/VLOOKUP(B16,'Pruefungen'!A2:E100,2,FALSE))
E17: =IF(A17="","",(SUMIF('Lernfortschritt'!B2:B100,B17,'Lernfortschritt'!D2:D100))/VLOOKUP(B17,'Pruefungen'!A2:E100,2,FALSE))
E18: =IF(A18="","",(SUMIF('Lernfortschritt'!B2:B100,B18,'Lernfortschritt'!D2:D100))/VLOOKUP(B18,'Pruefungen'!A2:E100,2,FALSE))
E19: =IF(A19="","",(SUMIF('Lernfortschritt'!B2:B100,B19,'Lernfortschritt'!D2:D100))/VLOOKUP(B19,'Pruefungen'!A2:E100,2,FALSE))
E20: =IF(A20="","",(SUMIF('Lernfortschritt'!B2:B100,B20,'Lernfortschritt'!D2:D100))/VLOOKUP(B20,'Pruefungen'!A2:E100,2,FALSE))
E21: =IF(A21="","",(SUMIF('Lernfortschritt'!B2:B100,B21,'Lernfortschritt'!D2:D100))/VLOOKUP(B21,'Pruefungen'!A2:E100,2,FALSE))
E22: =IF(A22="","",(SUMIF('Lernfortschritt'!B2:B100,B22,'Lernfortschritt'!D2:D100))/VLOOKUP(B22,'Pruefungen'!A2:E100,2,FALSE))
E23: =IF(A23="","",(SUMIF('Lernfortschritt'!B2:B100,B23,'Lernfortschritt'!D2:D100))/VLOOKUP(B23,'Pruefungen'!A2:E100,2,FALSE))
E24: =IF(A24="","",(SUMIF('Lernfortschritt'!B2:B100,B24,'Lernfortschritt'!D2:D100))/VLOOKUP(B24,'Pruefungen'!A2:E100,2,FALSE))
E25: =IF(A25="","",(SUMIF('Lernfortschritt'!B2:B100,B25,'Lernfortschritt'!D2:D100))/VLOOKUP(B25,'Pruefungen'!A2:E100,2,FALSE))
E26: =IF(A26="","",(SUMIF('Lernfortschritt'!B2:B100,B26,'Lernfortschritt'!D2:D100))/VLOOKUP(B26,'Pruefungen'!A2:E100,2,FALSE))
E27: =IF(A27="","",(SUMIF('Lernfortschritt'!B2:B100,B27,'Lernfortschritt'!D2:D100))/VLOOKUP(B27,'Pruefungen'!A2:E100,2,FALSE))
E28: =IF(A28="","",(SUMIF('Lernfortschritt'!B2:B100,B28,'Lernfortschritt'!D2:D100))/VLOOKUP(B28,'Pruefungen'!A2:E100,2,FALSE))
E29: =IF(A29="","",(SUMIF('Lernfortschritt'!B2:B100,B29,'Lernfortschritt'!D2:D100))/VLOOKUP(B29,'Pruefungen'!A2:E100,2,FALSE))
E30: =IF(A30="","",(SUMIF('Lernfortschritt'!B2:B100,B30,'Lernfortschritt'!D2:D100))/VLOOKUP(B30,'Pruefungen'!A2:E100,2,FALSE))
E31: =IF(A31="","",(SUMIF('Lernfortschritt'!B2:B100,B31,'Lernfortschritt'!D2:D100))/VLOOKUP(B31,'Pruefungen'!A2:E100,2,FALSE))
E32: =IF(A32="","",(SUMIF('Lernfortschritt'!B2:B100,B32,'Lernfortschritt'!D2:D100))/VLOOKUP(B32,'Pruefungen'!A2:E100,2,FALSE))
E33: =IF(A33="","",(SUMIF('Lernfortschritt'!B2:B100,B33,'Lernfortschritt'!D2:D100))/VLOOKUP(B33,'Pruefungen'!A2:E100,2,FALSE))
E34: =IF(A34="","",(SUMIF('Lernfortschritt'!B2:B100,B34,'Lernfortschritt'!D2:D100))/VLOOKUP(B34,'Pruefungen'!A2:E100,2,FALSE))
E35: =IF(A35="","",(SUMIF('Lernfortschritt'!B2:B100,B35,'Lernfortschritt'!D2:D100))/VLOOKUP(B35,'Pruefungen'!A2:E100,2,FALSE))
E36: =IF(A36="","",(SUMIF('Lernfortschritt'!B2:B100,B36,'Lernfortschritt'!D2:D100))/VLOOKUP(B36,'Pruefungen'!A2:E100,2,FALSE))
E37: =IF(A37="","",(SUMIF('Lernfortschritt'!B2:B100,B37,'Lernfortschritt'!D2:D100))/VLOOKUP(B37,'Pruefungen'!A2:E100,2,FALSE))
E38: =IF(A38="","",(SUMIF('Lernfortschritt'!B2:B100,B38,'Lernfortschritt'!D2:D100))/VLOOKUP(B38,'Pruefungen'!A2:E100,2,FALSE))
E39: =IF(A39="","",(SUMIF('Lernfortschritt'!B2:B100,B39,'Lernfortschritt'!D2:D100))/VLOOKUP(B39,'Pruefungen'!A2:E100,2,FALSE))
E40: =IF(A40="","",(SUMIF('Lernfortschritt'!B2:B100,B40,'Lernfortschritt'!D2:D100))/VLOOKUP(B40,'Pruefungen'!A2:E100,2,FALSE))
...

Sheet Kosten
A1: Datum | B1: Kategorie | C1: Beschreibung | D1: Betrag | E1: Zahlungsart
A2: 46032 | B2: Bücher | C2: Mathe-Skript | D2: 24.99 | E2: Kreditkarte
A3: 46034 | B3: Kurs | C3: Online-Tutorium | D3: 49.9 | E3: PayPal
A4: 46036 | B4: Material | C4: Notizblöcke | D4: 5.99 | E4: Bar
