Workbook

Sheet Accueil
C2: YouTube Content ROI Tracker & Budget Planner 2026
C3: Maximisez votre retour sur investissement avec ce tracker complet qui analyse les performances de vos vidéos et optimise votre budget de production.
C5: Mode d'emploi
B6: 1. | C6: Importez vos données YouTube
B7: 2. | C7: Saisissez vos coûts de production
B8: 3. | C8: Analysez vos performances clés
B9: 4. | C9: Optimisez votre budget mensuel
B10: 5. | C10: Identifiez les opportunités de croissance
B11: 6. | C11: Générez des rapports personnalisés
C13: Remplissez uniquement les cellules blanches – les colonnes vertes se calculent seules.
C15: Aller à la feuille
C16: → Tableau de bord
C17: → Depenses
C18: → Performances
C19: → Dashboard
C21: Créé par Haiktec · haiktec.tech

Sheet Tableau de bord
B2: Tableau de bord – YouTube Content ROI Tracker & Budget Planner 2026
B4: Indicateurs
B5: Total dépenses | C5: =SUM(Depenses!D2:D300)
B6: Total recettes | C6: =SUM(Performances!E2:E300)
B7: ROI moyen | C7: =AVERAGE(Performances!F2:F300)
B8: Vidéo la plus rentable | C8: =INDEX(Performances!B2:B300, MATCH(MAX(Performances!F2:F300), Performances!F2:F300, 0))
B9: Vues totales | C9: =SUM(Performances!C2:C300)

Sheet Depenses
A1: Date | B1: Type | C1: Description | D1: Montant
A2: 46027 | B2: Matériel | C2: Nouveau micro | D2: 199.99
A3: 46034 | B3: Logiciel | C3: Abonnement annuel | D3: 120
A4: 46040 | B4: Location | C4: Studio journée | D4: 250
A5: 46047 | B5: Graphisme | C5: Miniature vidéo | D5: 80

Sheet Performances
A1: Date | B1: Titre | C1: Vues | D1: Duree | E1: Recettes | F1: ROI
A2: 46029 | B2: Tutoriel débutants | C2: 12543 | D2: 0:15 | E2: 56.2 | F2: =E2/INDEX(Depenses!D2:D300, MATCH(A2, Depenses!A2:A300, 0))
A3: 46036 | B3: Revue produit | C3: 8932 | D3: 0:12 | E3: 42.5 | F3: =E3/INDEX(Depenses!D2:D300, MATCH(A3, Depenses!A2:A300, 0))
A4: 46043 | B4: VLOG journalier | C4: 21005 | D4: 0:08 | E4: 38.9 | F4: =E4/INDEX(Depenses!D2:D300, MATCH(A4, Depenses!A2:A300, 0))
F5: =IF(A5="","",E5/INDEX(Depenses!D2:D300, MATCH(A5, Depenses!A2:A300, 0)))
F6: =IF(A6="","",E6/INDEX(Depenses!D2:D300, MATCH(A6, Depenses!A2:A300, 0)))
F7: =IF(A7="","",E7/INDEX(Depenses!D2:D300, MATCH(A7, Depenses!A2:A300, 0)))
F8: =IF(A8="","",E8/INDEX(Depenses!D2:D300, MATCH(A8, Depenses!A2:A300, 0)))
F9: =IF(A9="","",E9/INDEX(Depenses!D2:D300, MATCH(A9, Depenses!A2:A300, 0)))
F10: =IF(A10="","",E10/INDEX(Depenses!D2:D300, MATCH(A10, Depenses!A2:A300, 0)))
F11: =IF(A11="","",E11/INDEX(Depenses!D2:D300, MATCH(A11, Depenses!A2:A300, 0)))
F12: =IF(A12="","",E12/INDEX(Depenses!D2:D300, MATCH(A12, Depenses!A2:A300, 0)))
F13: =IF(A13="","",E13/INDEX(Depenses!D2:D300, MATCH(A13, Depenses!A2:A300, 0)))
F14: =IF(A14="","",E14/INDEX(Depenses!D2:D300, MATCH(A14, Depenses!A2:A300, 0)))
F15: =IF(A15="","",E15/INDEX(Depenses!D2:D300, MATCH(A15, Depenses!A2:A300, 0)))
F16: =IF(A16="","",E16/INDEX(Depenses!D2:D300, MATCH(A16, Depenses!A2:A300, 0)))
F17: =IF(A17="","",E17/INDEX(Depenses!D2:D300, MATCH(A17, Depenses!A2:A300, 0)))
F18: =IF(A18="","",E18/INDEX(Depenses!D2:D300, MATCH(A18, Depenses!A2:A300, 0)))
F19: =IF(A19="","",E19/INDEX(Depenses!D2:D300, MATCH(A19, Depenses!A2:A300, 0)))
F20: =IF(A20="","",E20/INDEX(Depenses!D2:D300, MATCH(A20, Depenses!A2:A300, 0)))
F21: =IF(A21="","",E21/INDEX(Depenses!D2:D300, MATCH(A21, Depenses!A2:A300, 0)))
F22: =IF(A22="","",E22/INDEX(Depenses!D2:D300, MATCH(A22, Depenses!A2:A300, 0)))
F23: =IF(A23="","",E23/INDEX(Depenses!D2:D300, MATCH(A23, Depenses!A2:A300, 0)))
F24: =IF(A24="","",E24/INDEX(Depenses!D2:D300, MATCH(A24, Depenses!A2:A300, 0)))
F25: =IF(A25="","",E25/INDEX(Depenses!D2:D300, MATCH(A25, Depenses!A2:A300, 0)))
F26: =IF(A26="","",E26/INDEX(Depenses!D2:D300, MATCH(A26, Depenses!A2:A300, 0)))
F27: =IF(A27="","",E27/INDEX(Depenses!D2:D300, MATCH(A27, Depenses!A2:A300, 0)))
F28: =IF(A28="","",E28/INDEX(Depenses!D2:D300, MATCH(A28, Depenses!A2:A300, 0)))
F29: =IF(A29="","",E29/INDEX(Depenses!D2:D300, MATCH(A29, Depenses!A2:A300, 0)))
F30: =IF(A30="","",E30/INDEX(Depenses!D2:D300, MATCH(A30, Depenses!A2:A300, 0)))
F31: =IF(A31="","",E31/INDEX(Depenses!D2:D300, MATCH(A31, Depenses!A2:A300, 0)))
F32: =IF(A32="","",E32/INDEX(Depenses!D2:D300, MATCH(A32, Depenses!A2:A300, 0)))
F33: =IF(A33="","",E33/INDEX(Depenses!D2:D300, MATCH(A33, Depenses!A2:A300, 0)))
F34: =IF(A34="","",E34/INDEX(Depenses!D2:D300, MATCH(A34, Depenses!A2:A300, 0)))
F35: =IF(A35="","",E35/INDEX(Depenses!D2:D300, MATCH(A35, Depenses!A2:A300, 0)))
F36: =IF(A36="","",E36/INDEX(Depenses!D2:D300, MATCH(A36, Depenses!A2:A300, 0)))
F37: =IF(A37="","",E37/INDEX(Depenses!D2:D300, MATCH(A37, Depenses!A2:A300, 0)))
F38: =IF(A38="","",E38/INDEX(Depenses!D2:D300, MATCH(A38, Depenses!A2:A300, 0)))
F39: =IF(A39="","",E39/INDEX(Depenses!D2:D300, MATCH(A39, Depenses!A2:A300, 0)))
F40: =IF(A40="","",E40/INDEX(Depenses!D2:D300, MATCH(A40, Depenses!A2:A300, 0)))
...

Sheet Dashboard
A1: KPI | B1: Valeur
